<mujoco model="magiclaw--in-hand">
    <compiler angle="radian" eulerseq="XYZ" />
    <asset>
        <mesh name="shell" file="../meshes/shell.stl" scale="0.001 0.001 0.001" />
        <mesh name="handle" file="../meshes/handle.stl" scale="0.001 0.001 0.001" />
        <mesh name="trigger" file="../meshes/trigger.stl" scale="0.001 0.001 0.001" />
        <mesh name="cold_shoe" file="../meshes/cold_shoe.stl" scale="0.001 0.001 0.001" />
        <mesh name="phone_holder" file="../meshes/phone_holder.stl" scale="0.001 0.001 0.001" />
        <mesh name="phone" file="../meshes/phone.stl" scale="0.001 0.001 0.001" />
        <mesh name="left_drive_beam" file="../meshes/left_drive_beam.stl" scale="0.001 0.001 0.001" />
        <mesh name="left_follow_beam" file="../meshes/left_follow_beam.stl" scale="0.001 0.001 0.001" />
        <mesh name="left_finger_base" file="../meshes/left_finger_base.stl" scale="0.001 0.001 0.001" />
        <mesh name="left_finger" file="../meshes/left_finger_surf.stl" scale="0.001 0.001 0.001" />
        <mesh name="right_drive_beam" file="../meshes/right_drive_beam.stl" scale="0.001 0.001 0.001" />
        <mesh name="right_follow_beam" file="../meshes/right_follow_beam.stl" scale="0.001 0.001 0.001" />
        <mesh name="right_finger_base" file="../meshes/right_finger_base.stl" scale="0.001 0.001 0.001" />
        <mesh name="right_finger" file="../meshes/right_finger_surf.stl" scale="0.001 0.001 0.001" />
        <mesh name="top_nameplate" file="../meshes/top_nameplate.stl" scale="0.001 0.001 0.001" />
        <mesh name="phone_camera" file="../meshes/phone_camera.stl" scale="0.001 0.001 0.001" />
        <mesh name="bottom_nameplate" file="../meshes/bottom_nameplate.stl" scale="0.001 0.001 0.001" />
    </asset>
    <worldbody>
        <light directional="true" pos="-0.5 0.5 3" dir="0 0 -1" />
        <geom pos="0 0 0" size="1 1 1" type="plane" rgba="1 0.83 0.61 0.5" />
        <body name="shell" pos="0.0 0.0 0.0" euler="0.0 -0.0 0.0">
            <geom name="shell_geom" type="mesh" mesh="shell" pos="0 0 0" euler="0 0 0" />
            <inertial mass="1.1547124958310249" pos="0.09215419082197362 -3.0360999473407925e-08 0.003155929862125859" fullinertia="0.0011731060061113516 0.002535696012427195 0.0021289998515155277 8.443177599909338e-09 0.00031236232114537456 -1.5227905621184584e-08" />
            <body name="handle" pos="0.06970274022901109 -1.7763568394002505e-17 -2.2142712203524214e-17" euler="-7.468827474833593e-16 -3.3920554541011573e-16 3.141592653589793">
                <geom name="handle_geom" type="mesh" mesh="handle" pos="0 0 0" euler="0 0 0" />
                <inertial mass="0.6418238445152238" pos="0.07852329032149423 -3.212940330378301e-07 -0.027412159974533404" fullinertia="0.0014048045539435078 0.00244021792605567 0.0015357716975840981 2.93639934211335e-09 0.0005206327549369438 9.413141346780289e-10" />
                <body name="trigger" pos="0.0 -3.944304526105059e-33 3.697785493223493e-33" euler="9.860761315262648e-32 4.930380657631324e-32 5.498214808145828e-33">
                    <geom name="trigger_geom" type="mesh" mesh="trigger" pos="0 0 0" euler="0 0 0" />
                    <inertial mass="0.3412860843603137" pos="0.0939227219234967 -5.809422311950623e-07 -0.023244604848516016" fullinertia="0.00014025758488175652 0.00034549430290121524 0.00022815403326676296 -1.4745741901814428e-08 0.00012868134776750572 5.1665036637637045e-09" />
                </body>
            </body>
            <body name="cold_shoe" pos="0.014228030288340117 -4.794371622907079e-07 0.0649445762063165" euler="1.570796326794898 -0.43633231299858233 3.1415926535897927">
                <geom name="cold_shoe_geom" type="mesh" mesh="cold_shoe" pos="0 0 0" euler="0 0 0" />
                <inertial mass="0.06809085000208817" pos="-0.0004682285408064077 0.006272933645659601 8.191619210524988e-18" fullinertia="4.601940388134735e-06 9.214205368077137e-06 6.473933916345846e-06 1.938227327744285e-07 1.6471966369020328e-20 3.498723544983655e-21" />
                <body name="phone_holder" pos="-0.0009499999999998443 0.01479999999999989 -1.4100523591624447e-17" euler="0.2708839278377749 1.2566370614359172 1.7963785889362146e-16">
                    <geom name="phone_holder_geom" type="mesh" mesh="phone_holder" pos="0 0 0" euler="0 0 0" />
                    <inertial mass="0.05440462887363338" pos="0.0006243933844416452 0.038638829025844965 -0.010505279263032874" fullinertia="3.778450593016228e-05 2.133704709883822e-05 5.212901213071338e-05 -1.2504612975426464e-07 -3.413793999174385e-07 9.252069012498977e-06" />
                    <body name="phone" pos="-5.230815780521425e-15 0.040351728941137796 -0.007543022429482527" euler="1.0802247528272196e-16 0.270883927837755 1.5707963267948963">
                        <geom name="phone_geom" type="mesh" mesh="phone" pos="0 0 0" euler="0 0 0" />
                        <inertial mass="0.5883914302022325" pos="0.00019571061796769653 0.0007302222847212891 0.0035262713385931037" fullinertia="0.0010493295288383684 0.00025022135000802285 0.0012943914287563507 -6.1008322796555256e-06 4.7327231065278025e-07 1.3768260114195368e-06" />
                        <body name="phone_camera" pos="0.023758707046508898 0.06175000190734866 -0.001250000000000031" euler="-5.5511151231257815e-17 6.938893903907227e-18 -1.5707963267948966">
                            <geom name="phone_camera_geom" type="mesh" mesh="phone_camera" pos="0 0 0" euler="0 0 0" />
                            <inertial mass="7.850000000000001e-06" pos="2.5106056556617462e-18 3.144186300207963e-18 0.0005000000000000059" fullinertia="1.3083333333572649e-12 1.3083333333215442e-12 1.308333333364686e-12 1.4109982669340974e-23 -1.5103341564744239e-24 -8.964993980166084e-24" />
                        </body>
                    </body>
                </body>
            </body>
            <body name="left_drive_beam" pos="0.09328751416757726 -0.0035000000000006714 0.0001999999999999591" euler="-3.1415926535897927 -7.68799573237438e-16 1.5707963267948966">
                <joint name="left_drive_beam2shell" type="hinge" axis="7.687995732374377e-16 -3.5188341897808857e-16 -1.0" pos="0.03500000000000066 0.03150048583242273 -2.5078040547888564e-17" />
                <geom name="left_drive_beam_geom" type="mesh" mesh="left_drive_beam" pos="0 0 0" euler="0 0 0" />
                <inertial mass="0.0886876201001314" pos="0.033871504520529824 0.04907050317929067 -1.1138369973577824e-08" fullinertia="4.451668816510309e-05 6.723346716196287e-06 4.1718345694979854e-05 -3.228241993904977e-06 7.584848964003694e-13 -1.6462224337643437e-11" />
                <body name="left_finger_base" pos="0.015947461351419986 0.09118905541354112 4.163336342344337e-19" euler="-3.141592653589793 2.070759876205155e-30 -3.141592653589793">
                    <joint name="left_finger_base2left_drive_beam" type="hinge" axis="-7.687995732374359e-16 -2.999214831565078e-16 1.0000000000000002" pos="-0.01905253864858069 0.0003114304188816475 4.654061351057062e-17" />
                    <geom name="left_finger_base_geom" type="mesh" mesh="left_finger_base" pos="0 0 0" euler="0 0 0" />
                    <inertial mass="0.21505299028592448" pos="-0.01476879182434422 0.03386384931816468 0.0001423892791908736" fullinertia="8.066081605719554e-05 6.384830054305602e-05 8.362190041833614e-05 2.317114021451734e-06 1.1471065987766742e-07 1.5573140016734295e-07" />
                    <body name="left_finger" pos="-0.013112878015285696 0.050575573969618336 1.1744077932362985e-16" euler="-1.5707963267948968 1.5857410828773072e-16 -0.24290271480331072">
                        <geom name="left_finger_geom" type="mesh" mesh="left_finger" pos="0 0 0" euler="0 0 0" />
                        <inertial mass="0.021403682367172116" pos="2.0391674460107367e-14 9.94003423654015e-16 0.0344736086972864" fullinertia="1.8565514805512384e-05 1.754210768244212e-05 6.282317846938596e-06 1.3912861520321421e-18 9.915367680558841e-18 -6.417075936887437e-20" />
                    </body>
                </body>
            </body>
            <body name="left_follow_beam" pos="0.1422875141675801 0.0034999999999999966 0.0001999999999999475" euler="-3.141592653589793 -6.404579899989633e-16 1.5707963267948966">
                <joint name="left_follow_beam2shell" type="hinge" axis="6.404579899989632e-16 -2.776437282460376e-16 -1.0" pos="0.0070000000000000045 0.010500485832419913 -5.093467830752557e-17" />
                <geom name="left_follow_beam_geom" type="mesh" mesh="left_follow_beam" pos="0 0 0" euler="0 0 0" />
                <inertial mass="0.07336934646340006" pos="0.00700000000002078 0.034295412045460744 -7.606090876475409e-18" fullinertia="3.0302030975941263e-05 4.57114469211224e-06 2.6551473727030785e-05 -1.1493463880457552e-17 -4.073573407389879e-18 -1.3802573759153775e-20" />
            </body>
            <body name="right_follow_beam" pos="0.1422875141675801 -0.017500000000000022 0.0001999999999999322" euler="-3.1415926535897927 -7.468827474833592e-16 1.5707963267948963">
                <joint name="right_follow_beam2shell" type="hinge" axis="7.468827474833592e-16 -3.6700121688494564e-16 -1.0000000000000002" pos="0.007000000000000024 0.010500485832419915 -6.644235773496602e-17" />
                <geom name="right_follow_beam_geom" type="mesh" mesh="right_follow_beam" pos="0 0 0" euler="0 0 0" />
                <inertial mass="0.07336934646340003" pos="0.007000000000020789 0.034295412045460764 -1.911247007288513e-18" fullinertia="3.0302030975940843e-05 4.571144692112222e-06 2.65514737270308e-05 -1.1466252287897632e-17 4.072185733128739e-18 4.435109780490989e-22" />
            </body>
            <body name="right_drive_beam" pos="0.09328751416757719 0.0035000000000005916 0.00019999999999996244" euler="-3.3219673273116006e-16 4.5825995775172895e-16 -1.5707963267948966">
                <joint name="right_drive_beam2shell" type="hinge" axis="4.58259957751729e-16 3.321967327311601e-16 -1.0000000000000002" pos="0.03500000000000061 0.031500485832422806 6.407106227090859e-17" />
                <geom name="right_drive_beam_geom" type="mesh" mesh="right_drive_beam" pos="0 0 0" euler="0 0 0" />
                <inertial mass="0.08868762015299468" pos="0.03387150453144859 0.049070503200715127 9.534665637759981e-09" fullinertia="4.451668823382398e-05 6.723346724523695e-06 4.171834576615709e-05 -3.2282420329719282e-06 -9.397976548638411e-13 1.3522874914890011e-11" />
                <body name="right_finger_base" pos="0.01594746135142 0.09118905541354103 2.7755575615628915e-18" euler="3.141592653589793 8.874685183736383e-31 3.141592653589793">
                    <joint name="right_finger_base2right_drive_beam" type="hinge" axis="4.582599577517281e-16 -2.6135038419890275e-16 -1.0000000000000004" pos="-0.01905253864858059 0.00031143041888179103 -8.126421819213156e-17" />
                    <geom name="right_finger_base_geom" type="mesh" mesh="right_finger_base" pos="0 0 0" euler="0 0 0" />
                    <inertial mass="0.21505288373601508" pos="-0.014768797598518374 0.03386385239866627 -0.00014238687017582806" fullinertia="8.066078096590805e-05 6.384828951789821e-05 8.362186535634816e-05 2.3171129203099837e-06 -1.1471139454705992e-07 -1.5572914780447696e-07" />
                    <body name="right_finger" pos="-0.013112876976025428 0.050575578034017785 6.776712331672819e-09" euler="1.5707974266846267 -3.8435449719296104e-16 2.898689938382873">
                        <geom name="right_finger_geom" type="mesh" mesh="right_finger" pos="0 0 0" euler="0 0 0" />
                        <inertial mass="0.13441512527440586" pos="4.507130953175978e-11 -3.490209281130484e-09 0.03447361220656389" fullinertia="0.00011659143299408017 0.00011016443626295465 3.9452956082812435e-05 -9.04960949561751e-18 -3.1199194829143395e-14 3.101400013090393e-14" />
                    </body>
                </body>
            </body>
            <body name="top_nameplate" pos="-0.04021505204144243 -1.430845204750933e-09 -0.14993500188494824" euler="1.570796326789443 -1.2246467991688608e-16 -3.943542306643651e-16">
                <geom name="top_nameplate_geom" type="mesh" mesh="top_nameplate" pos="0 0 0" euler="0 0 0" />
                <inertial mass="0.015352404118954797" pos="0.16470303570658185 0.17686499557403426 5.477253344567074e-07" fullinertia="4.1702791124881393e-07 3.3001411566793346e-06 2.95766933291813e-06 2.846977867808507e-07 -1.5249713805610626e-11 1.1973970697273085e-12" />
            </body>
            <body name="bottom_nameplate" pos="-0.040446025819163525 1.0873460992387375e-06 -0.21026843847429663" euler="1.570796326789449 1.22464679912587e-16 -3.943542306655768e-16">
                <geom name="bottom_nameplate_geom" type="mesh" mesh="bottom_nameplate" pos="0 0 0" euler="0 0 0" />
                <inertial mass="0.015352404118954797" pos="0.1647030357065819 0.17686499557403426 5.477253344578433e-07" fullinertia="4.170279112488256e-07 3.300141156678901e-06 2.9576693329177507e-06 2.846977867809787e-07 -1.5249713808317555e-11 1.1973970702360726e-12" />
            </body>
        </body>
    </worldbody>
</mujoco>