<?xml version='1.0' encoding='utf-8'?>
<robot name="magiclaw-in-hand">
    <material name="black">
        <color rgba="0.0 0.0 0.0 1.0" />
    </material>
    <material name="white">
        <color rgba="1.0 1.0 1.0 1.0" />
    </material>
    <material name="orange">
        <color rgba="1.0 0.2 0.0 1.0" />
    </material>
    <link name="shell">
        <inertial>
            <origin xyz="-3.036099948925442e-08 0.0031559298621258746 0.09215419082197411" rpy="0.0 0.0 0.0" />
            <mass value="1.1547124958310255" />
            <inertia ixx="0.002535696012427224" iyy="0.0021289998515154956" izz="0.0011731060061113323" ixy="-1.5227905624726843e-08" iyz="0.00031236232114537906" ixz="8.44317760337745e-09" />
        </inertial>
        <visual name="shell_visual">
            <origin xyz="0.0 0.0 0.0" rpy="0.0 0.0 0.0" />
            <geometry>
                <mesh filename="../meshes/shell.stl" scale="0.001 0.001 0.001" />
            </geometry>
            <material name="white" />
        </visual>
        <collision name="shell_collision">
            <origin xyz="0.0 0.0 0.0" rpy="0.0 0.0 0.0" />
            <geometry>
                <mesh filename="../meshes/shell.stl" scale="0.001 0.001 0.001" />
            </geometry>
        </collision>
    </link>
    <link name="handle">
        <inertial>
            <origin xyz="-0.07145222009278175 0.03448322997443732 3.212940330183801e-07" rpy="-9.964229544592797e-33 -0.0 -4.3790577010150533e-47" />
            <mass value="0.6418238445152238" />
            <inertia ixx="0.0014048045539321653" iyy="0.0015357716975954387" izz="0.002440217926055642" ixy="0.000520632754935519" iyz="9.413141340245053e-10" ixz="2.936399342693181e-09" />
        </inertial>
        <visual name="handle_visual">
            <origin xyz="0.0070710702290114735 0.007071070000759444 2.81836760458852e-17" rpy="-1.5707963267948966 5.886432702762434e-16 -3.1415926535788974" />
            <geometry>
                <mesh filename="../meshes/handle.stl" scale="0.001 0.001 0.001" />
            </geometry>
            <material name="white" />
        </visual>
        <collision name="handle_collision">
            <origin xyz="0.0070710702290114735 0.007071070000759444 2.81836760458852e-17" rpy="-1.5707963267948966 5.886432702762434e-16 -3.1415926535788974" />
            <geometry>
                <mesh filename="../meshes/handle.stl" scale="0.001 0.001 0.001" />
            </geometry>
        </collision>
    </link>
    <link name="trigger">
        <inertial>
            <origin xyz="5.80942231138317e-07 -0.023244604848252127 -0.09392272169473874" rpy="0.0 -0.0 0.0" />
            <mass value="0.3412860843603137" />
            <inertia ixx="0.00034549430290120077" iyy="0.00022815403326956025" izz="0.00014025758487895356" ixy="-5.166503663412203e-09" iyz="-0.00012868134776654886" ixz="-1.4745741901377342e-08" />
        </inertial>
        <visual name="trigger_visual">
            <origin xyz="1.0681082194022044e-16 -7.594980200309466e-13 2.290114675673749e-10" rpy="-1.5707963267948974 1.5707963267840002 0" />
            <geometry>
                <mesh filename="../meshes/trigger.stl" scale="0.001 0.001 0.001" />
            </geometry>
            <material name="black" />
        </visual>
        <collision name="trigger_collision">
            <origin xyz="1.0681082194022044e-16 -7.594980200309466e-13 2.290114675673749e-10" rpy="-1.5707963267948974 1.5707963267840002 0" />
            <geometry>
                <mesh filename="../meshes/trigger.stl" scale="0.001 0.001 0.001" />
            </geometry>
        </collision>
    </link>
    <link name="cold_shoe">
        <inertial>
            <origin xyz="5.628376235980177e-10 0.0004682304061861431 -0.006272930329425908" rpy="0.0 -2.7369110631344083e-48 0.0" />
            <mass value="0.06809085000208817" />
            <inertia ixx="6.473933916345846e-06" iyy="4.601940388130515e-06" izz="9.214205368081373e-06" ixy="-1.72932808178287e-20" iyz="1.9382273272418102e-07" ixz="-1.2579291351491548e-20" />
        </inertial>
        <visual name="cold_shoe_visual">
            <origin xyz="5.628376156079898e-10 1.865311387572177e-09 3.3162285895116383e-09" rpy="-1.5707963267948954 1.0896228364032353e-11 -1.5707963267948972" />
            <geometry>
                <mesh filename="../meshes/cold_shoe.stl" scale="0.001 0.001 0.001" />
            </geometry>
            <material name="black" />
        </visual>
        <collision name="cold_shoe_collision">
            <origin xyz="5.628376156079898e-10 1.865311387572177e-09 3.3162285895116383e-09" rpy="-1.5707963267948954 1.0896228364032353e-11 -1.5707963267948972" />
            <geometry>
                <mesh filename="../meshes/cold_shoe.stl" scale="0.001 0.001 0.001" />
            </geometry>
        </collision>
    </link>
    <link name="phone_holder">
        <inertial>
            <origin xyz="-0.0005268066449775594 -0.04504908884406679 -0.007601536238188604" rpy="0.0 -0.0 1.9446922743316068e-62" />
            <mass value="0.05440462887363338" />
            <inertia ixx="3.961233466886658e-05" iyy="2.484525781452656e-05" izz="4.6792972676320274e-05" ixy="-2.2460873848615303e-06" iyz="-1.3046661814739821e-05" ixz="4.759806514893799e-06" />
        </inertial>
        <visual name="phone_holder_visual">
            <origin xyz="5.628375854240723e-10 -0.008590994105572954 0.008958647039363892" rpy="-0.1849775528917408 -0.2838613060410977 -3.0051291026057503" />
            <geometry>
                <mesh filename="../meshes/phone_holder.stl" scale="0.001 0.001 0.001" />
            </geometry>
            <material name="white" />
        </visual>
        <collision name="phone_holder_collision">
            <origin xyz="5.628375854240723e-10 -0.008590994105572954 0.008958647039363892" rpy="-0.1849775528917408 -0.2838613060410977 -3.0051291026057503" />
            <geometry>
                <mesh filename="../meshes/phone_holder.stl" scale="0.001 0.001 0.001" />
            </geometry>
        </collision>
    </link>
    <link name="phone">
        <inertial>
            <origin xyz="0.0017841609149742898 0.0021811220995932245 -0.00225068416427491" rpy="-5.5511151231257815e-17 -0.0 0.0" />
            <mass value="0.5883914302022325" />
            <inertia ixx="0.0003507399980440597" iyy="0.0011126533569696115" izz="0.0011305489525890822" ixy="0.00019580632405262206" iyz="-7.175359769052297e-05" ixz="-0.0002377989388821909" />
        </inertial>
        <visual name="phone_visual">
            <origin xyz="4.823436108858381e-10 2.4976788814967676e-09 5.867082633059795e-09" rpy="2.827433388230821 -0.7072162408472138 1.5707963267948872" />
            <geometry>
                <mesh filename="../meshes/phone.stl" scale="0.001 0.001 0.001" />
            </geometry>
            <material name="black" />
        </visual>
        <collision name="phone_collision">
            <origin xyz="4.823436108858381e-10 2.4976788814967676e-09 5.867082633059795e-09" rpy="2.827433388230821 -0.7072162408472138 1.5707963267948872" />
            <geometry>
                <mesh filename="../meshes/phone.stl" scale="0.001 0.001 0.001" />
            </geometry>
        </collision>
    </link>
    <link name="left_drive_beam">
        <inertial>
            <origin xyz="-0.0011284954794705815 -0.017570507346870327 1.1136818920572112e-08" rpy="0.0 4.868505685310126e-48 2.1895288505075267e-47" />
            <mass value="0.0886876201001314" />
            <inertia ixx="4.4516688165101176e-05" iyy="6.723346716196743e-06" izz="4.1718345694979406e-05" ixy="3.2282419939048654e-06" iyz="-1.6462605615727972e-11" ixz="-7.584496504937351e-13" />
        </inertial>
        <visual name="left_drive_beam_visual">
            <origin xyz="-0.03500000000000053 0.03149999583242055 -1.0163804173290992e-12" rpy="-3.1415926535788974 3.4450928484728667e-16 3.469446951907011e-16" />
            <geometry>
                <mesh filename="../meshes/left_drive_beam.stl" scale="0.001 0.001 0.001" />
            </geometry>
            <material name="white" />
        </visual>
        <collision name="left_drive_beam_collision">
            <origin xyz="-0.03500000000000053 0.03149999583242055 -1.0163804173290992e-12" rpy="-3.1415926535788974 3.4450928484728667e-16 3.469446951907011e-16" />
            <geometry>
                <mesh filename="../meshes/left_drive_beam.stl" scale="0.001 0.001 0.001" />
            </geometry>
        </collision>
    </link>
    <link name="left_follow_beam">
        <inertial>
            <origin xyz="2.0938806244430452e-14 -0.02379541621304325 -1.9239711560037344e-12" rpy="0.0 4.868505685310126e-48 2.1895288505075267e-47" />
            <mass value="0.07336934646340006" />
            <inertia ixx="3.0302030975940707e-05" iyy="4.571144692112247e-06" izz="2.655147372703164e-05" ixy="1.1524273859374492e-17" iyz="-2.3948173649359456e-16" ixz="4.082604895037856e-18" />
        </inertial>
        <visual name="left_follow_beam_visual">
            <origin xyz="-0.006999999999999888 0.01049999583241764 -1.5503014150208828e-12" rpy="-3.1415926535788974 3.4450928484728667e-16 3.4694469519070103e-16" />
            <geometry>
                <mesh filename="../meshes/left_follow_beam.stl" scale="0.001 0.001 0.001" />
            </geometry>
            <material name="white" />
        </visual>
        <collision name="left_follow_beam_collision">
            <origin xyz="-0.006999999999999888 0.01049999583241764 -1.5503014150208828e-12" rpy="-3.1415926535788974 3.4450928484728667e-16 3.4694469519070103e-16" />
            <geometry>
                <mesh filename="../meshes/left_follow_beam.stl" scale="0.001 0.001 0.001" />
            </geometry>
        </collision>
    </link>
    <link name="left_finger_base">
        <inertial>
            <origin xyz="-0.0042837468242360455 -0.00014238927681188465 -0.033552908899287" rpy="0.0 -0.0 0.0" />
            <mass value="0.21505299028592448" />
            <inertia ixx="8.06608160571921e-05" iyy="8.362190041833053e-05" izz="6.384830054305968e-05" ixy="1.1471065985239519e-07" iyz="1.557314003827936e-07" ixz="2.317114021453014e-06" />
        </inertial>
        <visual name="left_finger_base_visual">
            <origin xyz="-0.019052538648580294 2.010030267229901e-12 0.00031094041887936186" rpy="0.0 9.044916178169453e-16 3.1415926535897927" />
            <geometry>
                <mesh filename="../meshes/left_finger_base.stl" scale="0.001 0.001 0.001" />
            </geometry>
            <material name="white" />
        </visual>
        <collision name="left_finger_base_collision">
            <origin xyz="-0.019052538648580294 2.010030267229901e-12 0.00031094041887936186" rpy="0.0 9.044916178169453e-16 3.1415926535897927" />
            <geometry>
                <mesh filename="../meshes/left_finger_base.stl" scale="0.001 0.001 0.001" />
            </geometry>
        </collision>
    </link>
    <link name="right_drive_beam">
        <inertial>
            <origin xyz="0.0011284954685521864 0.01757050736829477 -9.53311452847605e-09" rpy="0.0 -1.1447086359127566e-48 -2.1895288505075267e-47" />
            <mass value="0.08868762015299468" />
            <inertia ixx="4.451668823382268e-05" iyy="6.723346724524158e-06" izz="4.171834576615728e-05" ixy="3.228242032972017e-06" iyz="-1.3523256176876628e-11" ixz="-9.39762522322448e-13" />
        </inertial>
        <visual name="right_drive_beam_visual">
            <origin xyz="0.035000000000000815 -0.031499995832420566 1.016460006442177e-12" rpy="3.1415926535788974 3.4450928484895254e-16 3.1415926535897927" />
            <geometry>
                <mesh filename="../meshes/right_drive_beam.stl" scale="0.001 0.001 0.001" />
            </geometry>
            <material name="white" />
        </visual>
        <collision name="right_drive_beam_collision">
            <origin xyz="0.035000000000000815 -0.031499995832420566 1.016460006442177e-12" rpy="3.1415926535788974 3.4450928484895254e-16 3.1415926535897927" />
            <geometry>
                <mesh filename="../meshes/right_drive_beam.stl" scale="0.001 0.001 0.001" />
            </geometry>
        </collision>
    </link>
    <link name="right_follow_beam">
        <inertial>
            <origin xyz="2.0885515539248445e-14 -0.023795416213043322 -1.923997523800569e-12" rpy="0.0 4.868505685310126e-48 2.1895288505075267e-47" />
            <mass value="0.07336934646340003" />
            <inertia ixx="3.0302030975940273e-05" iyy="4.571144692112254e-06" izz="2.6551473727031205e-05" ixy="1.1524273859374492e-17" iyz="-2.394978301195924e-16" ixz="-4.048620231027789e-18" />
        </inertial>
        <visual name="right_follow_beam_visual">
            <origin xyz="-0.006999999999999926 0.010499995832417586 -1.550322058230247e-12" rpy="-3.1415926535788974 3.4450928484728677e-16 3.4694469519070108e-16" />
            <geometry>
                <mesh filename="../meshes/right_follow_beam.stl" scale="0.001 0.001 0.001" />
            </geometry>
            <material name="white" />
        </visual>
        <collision name="right_follow_beam_collision">
            <origin xyz="-0.006999999999999926 0.010499995832417586 -1.550322058230247e-12" rpy="-3.1415926535788974 3.4450928484728677e-16 3.4694469519070108e-16" />
            <geometry>
                <mesh filename="../meshes/right_follow_beam.stl" scale="0.001 0.001 0.001" />
            </geometry>
        </collision>
    </link>
    <link name="right_finger_base">
        <inertial>
            <origin xyz="0.004283741050062497 0.0001423868677968178 0.033552911979788685" rpy="0.0 2.7369110631344083e-48 1.2703435263948184e-48" />
            <mass value="0.21505288373601508" />
            <inertia ixx="8.066078096590279e-05" iyy="8.36218653563442e-05" izz="6.384828951790173e-05" ixy="1.1471139452181839e-07" iyz="1.5572914801996807e-07" ixz="2.3171129203110695e-06" />
        </inertial>
        <visual name="right_finger_base_visual">
            <origin xyz="0.019052538648580843 -2.010039287791976e-12 -0.0003109404188792908" rpy="0.0 9.298117830909563e-16 1.9375873915495425e-16" />
            <geometry>
                <mesh filename="../meshes/right_finger_base.stl" scale="0.001 0.001 0.001" />
            </geometry>
            <material name="white" />
        </visual>
        <collision name="right_finger_base_collision">
            <origin xyz="0.019052538648580843 -2.010039287791976e-12 -0.0003109404188792908" rpy="0.0 9.298117830909563e-16 1.9375873915495425e-16" />
            <geometry>
                <mesh filename="../meshes/right_finger_base.stl" scale="0.001 0.001 0.001" />
            </geometry>
        </collision>
    </link>
    <link name="top_nameplate">
        <inertial>
            <origin xyz="-0.0036536991417720176 0.025490855844298298 -1.6305228137929461e-07" rpy="0.0 1.0097419586828951e-28 0.0" />
            <mass value="0.015352404118954797" />
            <inertia ixx="3.255843700771904e-06" iyy="4.613253671547791e-07" izz="2.9576693329146336e-06" ixy="4.5475833918546373e-07" iyz="-1.505911452439698e-11" ixz="2.6852536699532255e-12" />
        </inertial>
        <visual name="top_nameplate_visual">
            <origin xyz="0.2090167675249763 -0.08931153628284554 -7.107776158036012e-07" rpy="-2.646334061703523e-16 -8.745180958218667e-17 1.825614397596966" />
            <geometry>
                <mesh filename="../meshes/top_nameplate.stl" scale="0.001 0.001 0.001" />
            </geometry>
            <material name="black" />
        </visual>
        <collision name="top_nameplate_collision">
            <origin xyz="0.2090167675249763 -0.08931153628284554 -7.107776158036012e-07" rpy="-2.646334061703523e-16 -8.745180958218667e-17 1.825614397596966" />
            <geometry>
                <mesh filename="../meshes/top_nameplate.stl" scale="0.001 0.001 0.001" />
            </geometry>
        </collision>
    </link>
    <link name="fusion_camera">
        <inertial>
            <origin xyz="0.00015450943178469068 -0.0002009676500756008 0.00043097517340476624" rpy="0.0 -0.0 -4.276423536147513e-50" />
            <mass value="7.850000000000001e-06" />
            <inertia ixx="1.3083333333323905e-12" iyy="1.3083333333522428e-12" izz="1.3083333333059207e-12" ixy="-1.0101904577379033e-39" iyz="1.3234889800848443e-23" ixz="3.308577196033057e-24" />
        </inertial>
        <visual name="fusion_camera_visual">
            <origin xyz="9.345972173946392e-10 -7.242040034327601e-10 2.100918283787223e-10" rpy="-0.4558614807294952 -0.28386130604109727 -3.0051291026057507" />
            <geometry>
                <mesh filename="../meshes/fusion_camera.stl" scale="0.001 0.001 0.001" />
            </geometry>
            <material name="black" />
        </visual>
        <collision name="fusion_camera_collision">
            <origin xyz="9.345972173946392e-10 -7.242040034327601e-10 2.100918283787223e-10" rpy="-0.4558614807294952 -0.28386130604109727 -3.0051291026057507" />
            <geometry>
                <mesh filename="../meshes/fusion_camera.stl" scale="0.001 0.001 0.001" />
            </geometry>
        </collision>
    </link>
    <link name="fusion_camera_frame">
        <inertial>
            <origin xyz="-0.00043097517481661463 -0.00015450943178474397 -0.0002009676507678293" rpy="0.0 -0.0 0.0" />
            <mass value="7.850000000000001e-06" />
            <inertia ixx="1.3083333333588603e-12" iyy="1.3083333333588603e-12" izz="1.308333333325773e-12" ixy="9.926203664181097e-24" iyz="-1.3234889800848443e-23" ixz="1.3234817173758914e-23" />
        </inertial>
        <visual name="fusion_camera_visual">
            <origin xyz="-2.1150148299398097e-10 -9.345972706853445e-10 -7.24900921511562e-10" rpy="0.0 0.0 0.0" />
            <geometry>
                <mesh filename="../meshes/fusion_camera.stl" scale="0.001 0.001 0.001" />
            </geometry>
            <material name="black" />
        </visual>
        <collision name="fusion_camera_collision">
            <origin xyz="-2.1150148299398097e-10 -9.345972706853445e-10 -7.24900921511562e-10" rpy="0.0 0.0 0.0" />
            <geometry>
                <mesh filename="../meshes/fusion_camera.stl" scale="0.001 0.001 0.001" />
            </geometry>
        </collision>
    </link>
    <link name="bottom_nameplate">
        <inertial>
            <origin xyz="0.004275405884252886 0.02539397796491409 1.642753379795183e-07" rpy="2.0194839173657902e-28 8.077935669463161e-28 0.0" />
            <mass value="0.015352404118954797" />
            <inertia ixx="3.2319607250476997e-06" iyy="4.852083428798931e-07" izz="2.9576693329148233e-06" ixy="-5.22471208830097e-07" iyz="1.4989013045515555e-11" ixz="3.05237902614103e-12" />
        </inertial>
        <visual name="bottom_nameplate_visual">
            <origin xyz="-0.21113644897175576 -0.08417814174562548 7.120006724773188e-07" rpy="3.141592653589793 3.5422912439554716e-16 1.2915436464649086" />
            <geometry>
                <mesh filename="../meshes/bottom_nameplate.stl" scale="0.001 0.001 0.001" />
            </geometry>
            <material name="black" />
        </visual>
        <collision name="bottom_nameplate_collision">
            <origin xyz="-0.21113644897175576 -0.08417814174562548 7.120006724773188e-07" rpy="3.141592653589793 3.5422912439554716e-16 1.2915436464649086" />
            <geometry>
                <mesh filename="../meshes/bottom_nameplate.stl" scale="0.001 0.001 0.001" />
            </geometry>
        </collision>
    </link>
    <link name="left_finger">
        <inertial>
            <origin xyz="-0.004361075263572565 0.03466592669354679 0.01150397388213457" rpy="0.0 0.0 0.0" />
            <mass value="0.027435622521284314" />
            <inertia ixx="2.126865638006519e-05" iyy="7.83285851385581e-06" izz="2.1142586124191007e-05" ixy="-9.459525760735522e-07" iyz="-3.817473612497817e-06" ixz="-3.328331694281864e-08" />
        </inertial>
        <visual name="left_finger_visual">
            <origin xyz="0.0 0.0 0.0" rpy="0.0 0.0 0.0" />
            <geometry>
                <mesh filename="../meshes/left_finger_surf.stl" scale="0.001 0.001 0.001" />
            </geometry>
            <material name="orange" />
        </visual>
        <collision name="left_finger_collision">
            <origin xyz="0.0 0.0 0.0" rpy="0.0 0.0 0.0" />
            <geometry>
                <mesh filename="../meshes/left_finger_surf.stl" scale="0.001 0.001 0.001" />
            </geometry>
        </collision>
    </link>
    <link name="right_finger">
        <inertial>
            <origin xyz="0.004361075269338782 -0.03466592669354721 0.011503973883564968" rpy="0.0 0.0 0.0" />
            <mass value="0.027435622521284557" />
            <inertia ixx="2.1268656380105085e-05" iyy="7.832858513856389e-06" izz="2.114258612415022e-05" ixy="-9.459525757887423e-07" iyz="3.817473612566906e-06" ixz="3.3283316867366035e-08" />
        </inertial>
        <visual name="right_finger_visual">
            <origin xyz="0.0 0.0 0.0" rpy="0.0 0.0 0.0" />
            <geometry>
                <mesh filename="../meshes/right_finger_surf.stl" scale="0.001 0.001 0.001" />
            </geometry>
            <material name="orange" />
        </visual>
        <collision name="right_finger_collision">
            <origin xyz="0.0 0.0 0.0" rpy="0.0 0.0 0.0" />
            <geometry>
                <mesh filename="../meshes/right_finger_surf.stl" scale="0.001 0.001 0.001" />
            </geometry>
        </collision>
    </link>
    <joint name="handle2shell" type="fixed">
        <origin xyz="-2.015201214205886e-17 0.0070710700006824025 0.06263166999992288" rpy="-3.1415926535897922 -1.5707963267840008 0" />
        <parent link="shell" />
        <child link="handle" />
    </joint>
    <joint name="trigger2handle" type="fixed">
        <origin xyz="0.007071070000000006 0.007071070000000003 -8.980117438753288e-18" rpy="3.141592653589793 -1.5707963267948954 0" />
        <parent link="handle" />
        <child link="trigger" />
    </joint>
    <joint name="cold_shoe2shell" type="fixed">
        <origin xyz="-4.799999999774959e-07 0.06494458000015499 0.014228029999292388" rpy="2.0071286397825827 -3.4694469519687367e-16 -1.387778780743643e-16" />
        <parent link="shell" />
        <child link="cold_shoe" />
    </joint>
    <joint name="phone_holder2cold_shoe" type="fixed">
        <origin xyz="-1.2742424845314793e-17 0.012700004434082457 -0.010799999666818785" rpy="1.134464013796315 5.031018862825798e-17 -2.3460026240579452e-17" />
        <parent link="cold_shoe" />
        <child link="phone_holder" />
    </joint>
    <joint name="phone2phone_holder" type="fixed">
        <origin xyz="0.0010906700000000028 -0.047076400000000004 -0.005283640000000003" rpy="2.8707087257520376 1.9721522630525295e-31 5.551115123125783e-17" />
        <parent link="phone_holder" />
        <child link="phone" />
    </joint>
    <joint name="left_drive_beam2shell" type="continuous">
        <origin xyz="0.031499999999999875 0.0002000000013596339 0.12478750999999767" rpy="-1.5707963268057925 -3.469446951869478e-16 7.722029127451353e-16" />
        <parent link="shell" />
        <child link="left_drive_beam" />
        <axis xyz="9.109807908194958e-16 -4.9372513233583245e-17 0.9999999999999998" />
    </joint>
    <joint name="left_follow_beam2shell" type="continuous">
        <origin xyz="0.01049999999999991 0.00020000000166471837 0.1527875099999976" rpy="-1.5707963268057925 -3.469446951869478e-16 7.722029127451353e-16" />
        <parent link="shell" />
        <child link="left_follow_beam" />
        <axis xyz="9.109807908194958e-16 -4.9372513233583245e-17 0.9999999999999998" />
    </joint>
    <joint name="right_follow_beam2shell" type="continuous">
        <origin xyz="-0.010500000000000042 0.0002000000016647213 0.15278750999999757" rpy="-1.5707963268057925 -3.469446951869478e-16 7.722029127451353e-16" />
        <parent link="shell" />
        <child link="right_follow_beam" />
        <axis xyz="9.109807908194958e-16 -4.9372513233583245e-17 0.9999999999999998" />
    </joint>
    <joint name="right_drive_beam2shell" type="continuous">
        <origin xyz="-0.03149999999999998 0.00020000000135964266 0.12478750999999765" rpy="1.5707963267840008 -3.469446951910089e-16 3.994901459192242e-16" />
        <parent link="shell" />
        <child link="right_drive_beam" />
        <axis xyz="-5.382680239935863e-16 -7.739149810139875e-18 0.9999999999999998" />
    </joint>
    <joint name="right_finger_base2right_drive_beam" type="continuous">
        <origin xyz="8.881784197001253e-18 0.060000000000000074 4.510281037539699e-19" rpy="0.0 -5.382680239935868e-16 -1.8009393804046963e-31" />
        <parent link="right_drive_beam" />
        <child link="right_finger_base" />
        <axis xyz="-3.944304526105059e-31 0.0 1.0" />
    </joint>
    <joint name="left_finger_base2left_drive_beam" type="continuous">
        <origin xyz="8.881784197001253e-18 -0.060000000000000074 -2.949029909160572e-18" rpy="0.0 9.10980790819496e-16 2.8517360085299336e-31" />
        <parent link="left_drive_beam" />
        <child link="left_finger_base" />
        <axis xyz="0.0 0.0 1.0" />
    </joint>
    <joint name="fusion_camera2phone" type="fixed">
        <origin xyz="0.058341470000000006 0.004890510134681598 0.03084570491507006" rpy="-2.8707087257520376 -5.720038651728236e-17 -1.4821227114525488e-18" />
        <parent link="phone" />
        <child link="fusion_camera" />
    </joint>
    <joint name="fusion_camera_frame2fusion_camera" type="fixed">
        <origin xyz="0.00 0.00 0.00" rpy="-0.4558614807294952 -0.28386130604109727 -3.00512910260575077" />
        <parent link="fusion_camera" />
        <child link="fusion_camera_frame" />
    </joint>
    <joint name="top_nameplate2shell" type="fixed">
        <origin xyz="-7.100000000310087e-07 0.029819740001077562 0.09889925999967496" rpy="-1.5707963267963456 0.25192402054702323 -1.5707963268007117" />
        <parent link="shell" />
        <child link="top_nameplate" />
    </joint>
    <joint name="bottom_nameplate2shell" type="fixed">
        <origin xyz="3.799999999498466e-07 -0.030513689998924943 0.09866829000033231" rpy="1.5707963267965035 -0.2764489532604732 -1.5707963268007832" />
        <parent link="shell" />
        <child link="bottom_nameplate" />
    </joint>
    <joint name="left_finger2left_finger_base" type="fixed">
        <origin xyz="-0.00594 -0.050265 0.0" rpy="-1.5707963267965035 0.0 2.89869518158974" />
        <parent link="left_finger_base" />
        <child link="left_finger" />
    </joint>
    <joint name="right_finger2right_finger_base" type="fixed">
        <origin xyz="0.00594 0.050265 0.0" rpy="-1.5707963267965035 0.0 -0.242897472000051" />
        <parent link="right_finger_base" />
        <child link="right_finger" />
    </joint>
</robot>